Workbook

Sheet Financing Inputs
B1: Inputs
B2: ($ in 'mm)
B4: Sources & Uses | N4: Business Purchase Assumptions
B5: Sources | H5: Uses | N5: Deal Close | T5: 45657
B7: Equity 1 | F7: =+SUM(L7:L9)-F11-F8 -> 269.875 | H7: Equity Purchase Price | L7: =IF(L43=1,T11,T13) -> 2159 | N7: Total Outstaning Shares | T7: 200
B8: Equity 2 | F8: =(SUM($L$7:$L$9)-F11)*T26 -> 269.875 | H8: Funding Fees | L8: =CHOOSE(L18,0,L39,0,0,0) -> 0 | N8: Current Share Price | T8: 10
B9: Assumed Existing Debt 1 | F9: 300 | H9: Other Closing Fees | L9: =T29*T11 -> 0 | N9: Premium on current share price (%) | T9: 0.08
B10: Assumed Existing Debt 2 | F10: =IF(L48=1,23.831,0) -> 0 | H10: Existing Debt 1 | L10: =F9 -> 300 | N10: Implied Stock Price | T10: =T8*(1+T9) -> 10.8
B11: Debt | F11: =L7*CHOOSE(L18,L26,L37,0,0) -> 1619.25 | H11: Existing Debt 2 | L11: =F10 -> 0 | N11: Equity Value Offered | T11: =T10*T7 -> 2160
N12: Net Debt | T12: -1
N13: Enterprise Value | T13: =T12+T11 -> 2159
B14: Total Sources | F14: =SUM(F7:F13) -> 2459 | H14: Total Uses | L14: =SUM(L7:L11) -> 2459 | N14: 2024E EBITDA | T14: =_xlfn.XLOOKUP(T5,Financials!$T$6:$AN$6,Financials!$T$29:$AN$29,0,0) -> 312.97923
N15: 2024E EBITDA Multiple | T15: =IFERROR(T11/T14,"na") -> 6.9014164
B16: Debt Assumptions
N17: Exit Assumptions
B18: Debt Facility Selector | L18: 1 | N18: Investment Horizon | T18: 10
B19: 1 = Debt 1 | N19: Exit Date | T19: =EOMONTH(T5,T18*12) -> 49309
B20: 2 = Debt 2 | N20: EBITDA at Exit | T20: =_xlfn.XLOOKUP(T19,Financials!$T$6:$AN$6,Financials!$T$29:$AN$29,0,0) -> 362.48471
B21: 3 = No Debt | N21: EBITDA Multiple | T21: 5
N22: Business Proceeds | T22: =T20*T21 -> 1812.4235
B24: Debt 1 | N24: Inputs for Ownership %
B25: * Structured as a Mortgage | N25: Equity 1 | T25: 0.5
B26: Loan to Value (Purchase Price) | L26: 0.75 | N26: Equity 2 | T26: =1-T25 -> 0.5
B27: Fixed Coupon | L27: 0.09
B28: Amortization Profile (Years) | L28: 18 | N28: Other Assumptions
N29: Other Closing Fees | T29: 0
B30: Debt 2
B31: * Structured as a Corporate Loan | N31: Toggle to Fund Sr. Unsec. Notes at Maturity | T31: 3
N32: 1 = Cashflow + Equity (if required)
B33: Coupon | L33: 0.031 | N33: 2 = 100% Equity
B34: Step up Interest rate | J34: 46539 | L34: 0.01 | N34: 3 = Refinance by Debt (Toggle in cell T52)
B35: Step up Interest rate | J35: 46905 | L35: 0.005
B36: Amortization per Year | J36: =J35 -> 46905 | L36: =1/7 -> 0.14285714 | N36: Refinance of Senior Unsecured Notes Selector | T36: 1
B37: Loan to Value (Purchase Price) | L37: 0.55 | N37: 1 = Debt 1
B38: Funding Fees (%) | L38: 0.0075 | N38: 2 = Debt 2
B39: Total Funding Fees | L39: =IF(L18=2,L38*F11,0) -> 0
B41: Existing Debt Assumptions
B43: Rollover of Debt 1 | K43: (1 = Yes, 0 = No) >>> | L43: 0
B44: Interest Rate | L44: 0.08
B45: Amount O/S as of Dec 31, 2024 | L45: 200
...

Sheet Operating Inputs
B2: Operating Inputs
B4: Scenario Selector>>> | D4: 3 | F4: <<< ( 1 : Downside Case, 2 : Base Case, 3 : Upside Case)
F6: Downside Case | AB6: Base Case | AX6: Upside Case | BU6: Selected Case
B7: Particulars | F7: ='Financing Inputs'!$T$5 -> 45657 | H7: =EOMONTH(F7,12) -> 46022 | J7: =EOMONTH(H7,12) -> 46387 | L7: =EOMONTH(J7,12) -> 46752 | N7: =EOMONTH(L7,12) -> 47118 | P7: =EOMONTH(N7,12) -> 47483 | R7: =EOMONTH(P7,12) -> 47848 | T7: =EOMONTH(R7,12) -> 48213 | V7: =EOMONTH(T7,12) -> 48579 | X7: =EOMONTH(V7,12) -> 48944 | Z7: =EOMONTH(X7,12) -> 49309 | AB7: ='Financing Inputs'!$T$5 -> 45657 | AD7: 46022 | AF7: =EOMONTH(AD7,12) -> 46387 | AH7: =EOMONTH(AF7,12) -> 46752 | AJ7: =EOMONTH(AH7,12) -> 47118 | AL7: =EOMONTH(AJ7,12) -> 47483 | AN7: =EOMONTH(AL7,12) -> 47848 | AP7: =EOMONTH(AN7,12) -> 48213 | AR7: =EOMONTH(AP7,12) -> 48579 | AT7: =EOMONTH(AR7,12) -> 48944 | AV7: =EOMONTH(AT7,12) -> 49309 | AX7: ='Financing Inputs'!$T$5 -> 45657 | AZ7: 46022 | BB7: =EOMONTH(AZ7,12) -> 46387 | BD7: =EOMONTH(BB7,12) -> 46752 | BF7: =EOMONTH(BD7,12) -> 47118 | BH7: =EOMONTH(BF7,12) -> 47483 | BJ7: =EOMONTH(BH7,12) -> 47848 | BL7: =EOMONTH(BJ7,12) -> 48213 | BN7: =EOMONTH(BL7,12) -> 48579 | BP7: =EOMONTH(BN7,12) -> 48944 | BR7: =EOMONTH(BP7,12) -> 49309 | BU7: ='Financing Inputs'!T5 -> 45657 | BW7: =EOMONTH(BU7,12) -> 46022 | BY7: =EOMONTH(BW7,12) -> 46387 | CA7: =EOMONTH(BY7,12) -> 46752 | CC7: =EOMONTH(CA7,12) -> 47118 | CE7: =EOMONTH(CC7,12) -> 47483 | CG7: =EOMONTH(CE7,12) -> 47848 | CI7: =EOMONTH(CG7,12) -> 48213 | CK7: =EOMONTH(CI7,12) -> 48579 | CM7: =EOMONTH(CK7,12) -> 48944 | CO7: =EOMONTH(CM7,12) -> 49309
B10: Revenue Assumptions
B11: Segment 1 | D11: % Yr/Yr Growth | F11: 0.095 | H11: 0.08 | J11: 0.07 | L11: 0.06 | N11: 0.05 | P11: 0.04 | R11: -0.03 | T11: =+R11 -> -0.03 | V11: =+T11 -> -0.03 | X11: =+V11 -> -0.03 | Z11: =+X11 -> -0.03 | AB11: 0.095 | AD11: 0.08 | AF11: 0.07 | AH11: 0.06 | AJ11: 0.05 | AL11: 0.04 | AN11: -0.03 | AP11: =AN11 -> -0.03 | AR11: =AP11 -> -0.03 | AT11: =AR11 -> -0.03 | AV11: =AT11 -> -0.03 | AX11: 0.095 | AZ11: 0.08 | BB11: 0.07 | BD11: 0.06 | BF11: 0.05 | BH11: 0.04 | BJ11: -0.03 | BL11: =+BJ11 -> -0.03 | BN11: =+BL11 -> -0.03 | BP11: =+BN11 -> -0.03 | BR11: =+BP11 -> -0.03 | BU11: =CHOOSE($D$4,F11,AB11,AX11) -> 0.095 | BW11: =CHOOSE($D$4,H11,AD11,AZ11) -> 0.08 | BY11: =CHOOSE($D$4,J11,AF11,BB11) -> 0.07 | CA11: =CHOOSE($D$4,L11,AH11,BD11) -> 0.06 | CC11: =CHOOSE($D$4,N11,AJ11,BF11) -> 0.05 | CE11: =CHOOSE($D$4,P11,AL11,BH11) -> 0.04 | CG11: =CHOOSE($D$4,R11,AN11,BJ11) -> -0.03 | CI11: =CHOOSE($D$4,T11,AP11,BL11) -> -0.03 | CK11: =CHOOSE($D$4,V11,AR11,BN11) -> -0.03 | CM11: =CHOOSE($D$4,X11,AT11,BP11) -> -0.03 | CO11: =CHOOSE($D$4,Z11,AV11,BR11) -> -0.03
B12: Segment 2 | D12: % Yr/Yr Growth | F12: 0.1 | H12: 0.1 | J12: 0.1 | L12: 0.1 | N12: 0.08 | P12: 0.08 | R12: -0.01 | T12: =+R12 -> -0.01 | V12: =+T12 -> -0.01 | X12: =+V12 -> -0.01 | Z12: =+X12 -> -0.01 | AB12: 0.1 | AD12: 0.1 | AF12: 0.1 | AH12: 0.1 | AJ12: 0.08 | AL12: 0.08 | AN12: -0.01 | AP12: =AN12 -> -0.01 | AR12: =AP12 -> -0.01 | AT12: =AR12 -> -0.01 | AV12: =AT12 -> -0.01 | AX12: 0.1 | AZ12: 0.1 | BB12: 0.1 | BD12: 0.1 | BF12: 0.08 | BH12: 0.08 | BJ12: -0.01 | BL12: =+BJ12 -> -0.01 | BN12: =+BL12 -> -0.01 | BP12: =+BN12 -> -0.01 | BR12: =+BP12 -> -0.01 | BU12: =CHOOSE($D$4,F12,AB12,AX12) -> 0.1 | BW12: =CHOOSE($D$4,H12,AD12,AZ12) -> 0.1 | BY12: =CHOOSE($D$4,J12,AF12,BB12) -> 0.1 | CA12: =CHOOSE($D$4,L12,AH12,BD12) -> 0.1 | CC12: =CHOOSE($D$4,N12,AJ12,BF12) -> 0.08 | CE12: =CHOOSE($D$4,P12,AL12,BH12) -> 0.08 | CG12: =CHOOSE($D$4,R12,AN12,BJ12) -> -0.01 | CI12: =CHOOSE($D$4,T12,AP12,BL12) -> -0.01 | CK12: =CHOOSE($D$4,V12,AR12,BN12) -> -0.01 | CM12: =CHOOSE($D$4,X12,AT12,BP12) -> -0.01 | CO12: =CHOOSE($D$4,Z12,AV12,BR12) -> -0.01
B13: Segment 3 | D13: % Yr/Yr Growth | F13: -0.28 | H13: -0.23 | J13: 0.02 | L13: 0.02 | N13: 0.02 | P13: 0.02 | R13: 0.02 | T13: =+R13 -> 0.02 | V13: =+T13 -> 0.02 | X13: =+V13 -> 0.02 | Z13: =+X13 -> 0.02 | AB13: -0.28 | AD13: -0.23 | AF13: 0.02 | AH13: 0.02 | AJ13: 0.02 | AL13: 0.02 | AN13: 0.02 | AP13: =AN13 -> 0.02 | AR13: =AP13 -> 0.02 | AT13: =AR13 -> 0.02 | AV13: =AT13 -> 0.02 | AX13: -0.28 | AZ13: -0.23 | BB13: 0.02 | BD13: 0.02 | BF13: 0.02 | BH13: 0.02 | BJ13: 0.02 | BL13: =+BJ13 -> 0.02 | BN13: =+BL13 -> 0.02 | BP13: =+BN13 -> 0.02 | BR13: =+BP13 -> 0.02 | BU13: =CHOOSE($D$4,F13,AB13,AX13) -> -0.28 | BW13: =CHOOSE($D$4,H13,AD13,AZ13) -> -0.23 | BY13: =CHOOSE($D$4,J13,AF13,BB13) -> 0.02 | CA13: =CHOOSE($D$4,L13,AH13,BD13) -> 0.02 | CC13: =CHOOSE($D$4,N13,AJ13,BF13) -> 0.02 | CE13: =CHOOSE($D$4,P13,AL13,BH13) -> 0.02 | CG13: =CHOOSE($D$4,R13,AN13,BJ13) -> 0.02 | CI13: =CHOOSE($D$4,T13,AP13,BL13) -> 0.02 | CK13: =CHOOSE($D$4,V13,AR13,BN13) -> 0.02 | CM13: =CHOOSE($D$4,X13,AT13,BP13) -> 0.02 | CO13: =CHOOSE($D$4,Z13,AV13,BR13) -> 0.02
B14: Segment 4 | D14: % Yr/Yr Growth | F14: 0.02 | H14: 0 | J14: 0 | L14: 0 | N14: 0 | P14: 0 | R14: 0 | T14: =+R14 -> 0 | V14: =+T14 -> 0 | X14: =+V14 -> 0 | Z14: =+X14 -> 0 | AB14: 0.02 | AD14: 0 | AF14: 0 | AH14: 0 | AJ14: 0 | AL14: 0 | AN14: 0 | AP14: =AN14 -> 0 | AR14: =AP14 -> 0 | AT14: =AR14 -> 0 | AV14: =AT14 -> 0 | AX14: 0.02 | AZ14: 0 | BB14: 0 | BD14: 0 | BF14: 0 | BH14: 0 | BJ14: 0 | BL14: =+BJ14 -> 0 | BN14: =+BL14 -> 0 | BP14: =+BN14 -> 0 | BR14: =+BP14 -> 0 | BU14: =CHOOSE($D$4,F14,AB14,AX14) -> 0.02 | BW14: =CHOOSE($D$4,H14,AD14,AZ14) -> 0 | BY14: =CHOOSE($D$4,J14,AF14,BB14) -> 0 | CA14: =CHOOSE($D$4,L14,AH14,BD14) -> 0 | CC14: =CHOOSE($D$4,N14,AJ14,BF14) -> 0 | CE14: =CHOOSE($D$4,P14,AL14,BH14) -> 0 | CG14: =CHOOSE($D$4,R14,AN14,BJ14) -> 0 | CI14: =CHOOSE($D$4,T14,AP14,BL14) -> 0 | CK14: =CHOOSE($D$4,V14,AR14,BN14) -> 0 | CM14: =CHOOSE($D$4,X14,AT14,BP14) -> 0 | CO14: =CHOOSE($D$4,Z14,AV14,BR14) -> 0
B15: Segment 5 | D15: % Yr/Yr Growth | F15: 0.04 | H15: 0.04 | J15: 0.04 | L15: 0.04 | N15: 0.04 | P15: 0.04 | R15: 0.04 | T15: =+R15 -> 0.04 | V15: =+T15 -> 0.04 | X15: =+V15 -> 0.04 | Z15: =+X15 -> 0.04 | AB15: 0.04 | AD15: 0.04 | AF15: 0.04 | AH15: 0.04 | AJ15: 0.04 | AL15: 0.04 | AN15: 0.04 | AP15: =AN15 -> 0.04 | AR15: =AP15 -> 0.04 | AT15: =AR15 -> 0.04 | AV15: =AT15 -> 0.04 | AX15: 0.04 | AZ15: 0.04 | BB15: 0.04 | BD15: 0.04 | BF15: 0.04 | BH15: 0.04 | BJ15: 0.04 | BL15: =+BJ15 -> 0.04 | BN15: =+BL15 -> 0.04 | BP15: =+BN15 -> 0.04 | BR15: =+BP15 -> 0.04 | BU15: =CHOOSE($D$4,F15,AB15,AX15) -> 0.04 | BW15: =CHOOSE($D$4,H15,AD15,AZ15) -> 0.04 | BY15: =CHOOSE($D$4,J15,AF15,BB15) -> 0.04 | CA15: =CHOOSE($D$4,L15,AH15,BD15) -> 0.04 | CC15: =CHOOSE($D$4,N15,AJ15,BF15) -> 0.04 | CE15: =CHOOSE($D$4,P15,AL15,BH15) -> 0.04 | CG15: =CHOOSE($D$4,R15,AN15,BJ15) -> 0.04 | CI15: =CHOOSE($D$4,T15,AP15,BL15) -> 0.04 | CK15: =CHOOSE($D$4,V15,AR15,BN15) -> 0.04 | CM15: =CHOOSE($D$4,X15,AT15,BP15) -> 0.04 | CO15: =CHOOSE($D$4,Z15,AV15,BR15) -> 0.04
B17: Gross Margin (%) | D17: % Margin | F17: 0.3 | H17: =+F17 -> 0.3 | J17: =+H17 -> 0.3 | L17: =+J17 -> 0.3 | N17: =+L17 -> 0.3 | P17: =+N17 -> 0.3 | R17: =+P17 -> 0.3 | T17: =+R17 -> 0.3 | V17: =+T17 -> 0.3 | X17: =+V17 -> 0.3 | Z17: =+X17 -> 0.3 | AB17: 0.3 | AD17: =+AB17 -> 0.3 | AF17: =+AD17 -> 0.3 | AH17: =+AF17 -> 0.3 | AJ17: =+AH17 -> 0.3 | AL17: =+AJ17 -> 0.3 | AN17: =+AL17 -> 0.3 | AP17: =+AN17 -> 0.3 | AR17: =+AP17 -> 0.3 | AT17: =+AR17 -> 0.3 | AV17: =+AT17 -> 0.3 | AX17: 0.3 | AZ17: =+AX17 -> 0.3 | BB17: =+AZ17 -> 0.3 | BD17: =+BB17 -> 0.3 | BF17: =+BD17 -> 0.3 | BH17: =+BF17 -> 0.3 | BJ17: =+BH17 -> 0.3 | BL17: =+BJ17 -> 0.3 | BN17: =+BL17 -> 0.3 | BP17: =+BN17 -> 0.3 | BR17: =+BP17 -> 0.3 | BU17: =CHOOSE($D$4,F17,AB17,AX17) -> 0.3 | BW17: =CHOOSE($D$4,H17,AD17,AZ17) -> 0.3 | BY17: =CHOOSE($D$4,J17,AF17,BB17) -> 0.3 | CA17: =CHOOSE($D$4,L17,AH17,BD17) -> 0.3 | CC17: =CHOOSE($D$4,N17,AJ17,BF17) -> 0.3 | CE17: =CHOOSE($D$4,P17,AL17,BH17) -> 0.3 | CG17: =CHOOSE($D$4,R17,AN17,BJ17) -> 0.3 | CI17: =CHOOSE($D$4,T17,AP17,BL17) -> 0.3 | CK17: =CHOOSE($D$4,V17,AR17,BN17) -> 0.3 | CM17: =CHOOSE($D$4,X17,AT17,BP17) -> 0.3 | CO17: =CHOOSE($D$4,Z17,AV17,BR17) -> 0.3
B19: Expenses Assumptions
B20: SG&A | D20: % of Total Revenue | F20: 0.108 | H20: 0.08 | J20: =+H20 -> 0.08 | L20: =+J20 -> 0.08 | N20: =+L20 -> 0.08 | P20: =+N20 -> 0.08 | R20: =+P20 -> 0.08 | T20: =+R20 -> 0.08 | V20: =+T20 -> 0.08 | X20: =+V20 -> 0.08 | Z20: =+X20 -> 0.08 | AB20: 0.068 | AD20: =+AB20 -> 0.068 | AF20: =+AD20 -> 0.068 | AH20: =+AF20 -> 0.068 | AJ20: =+AH20 -> 0.068 | AL20: =+AJ20 -> 0.068 | AN20: =+AL20 -> 0.068 | AP20: =+AN20 -> 0.068 | AR20: =+AP20 -> 0.068 | AT20: =+AR20 -> 0.068 | AV20: =+AT20 -> 0.068 | AX20: 0.048 | AZ20: =+AX20 -> 0.048 | BB20: =+AZ20 -> 0.048 | BD20: =+BB20 -> 0.048 | BF20: =+BD20 -> 0.048 | BH20: =+BF20 -> 0.048 | BJ20: =+BH20 -> 0.048 | BL20: =+BJ20 -> 0.048 | BN20: =+BL20 -> 0.048 | BP20: =+BN20 -> 0.048 | BR20: =+BP20 -> 0.048 | BU20: =CHOOSE($D$4,F20,AB20,AX20) -> 0.048 | BW20: =CHOOSE($D$4,H20,AD20,AZ20) -> 0.048 | BY20: =CHOOSE($D$4,J20,AF20,BB20) -> 0.048 | CA20: =CHOOSE($D$4,L20,AH20,BD20) -> 0.048 | CC20: =CHOOSE($D$4,N20,AJ20,BF20) -> 0.048 | CE20: =CHOOSE($D$4,P20,AL20,BH20) -> 0.048 | CG20: =CHOOSE($D$4,R20,AN20,BJ20) -> 0.048 | CI20: =CHOOSE($D$4,T20,AP20,BL20) -> 0.048 | CK20: =CHOOSE($D$4,V20,AR20,BN20) -> 0.048 | CM20: =CHOOSE($D$4,X20,AT20,BP20) -> 0.048 | CO20: =CHOOSE($D$4,Z20,AV20,BR20) -> 0.048
B22: Capital Expenditure | D22: in $'mm | F22: 30.02 | H22: =+F22 -> 30.02 | J22: =+H22 -> 30.02 | L22: =+J22 -> 30.02 | N22: =+L22 -> 30.02 | P22: =+N22 -> 30.02 | R22: =+P22 -> 30.02 | T22: =+R22 -> 30.02 | V22: =+T22 -> 30.02 | X22: =+V22 -> 30.02 | Z22: =+X22 -> 30.02 | AB22: 35 | AD22: =+AB22 -> 35 | AF22: =+AD22 -> 35 | AH22: =+AF22 -> 35 | AJ22: =+AH22 -> 35 | AL22: =+AJ22 -> 35 | AN22: =+AL22 -> 35 | AP22: =+AN22 -> 35 | AR22: =+AP22 -> 35 | AT22: =+AR22 -> 35 | AV22: =+AT22 -> 35 | AX22: 40 | AZ22: =+AX22 -> 40 | BB22: =+AZ22 -> 40 | BD22: =+BB22 -> 40 | BF22: =+BD22 -> 40 | BH22: =+BF22 -> 40 | BJ22: =+BH22 -> 40 | BL22: =+BJ22 -> 40 | BN22: =+BL22 -> 40 | BP22: =+BN22 -> 40 | BR22: =+BP22 -> 40 | BU22: =CHOOSE($D$4,F22,AB22,AX22) -> 40 | BW22: =CHOOSE($D$4,H22,AD22,AZ22) -> 40 | BY22: =CHOOSE($D$4,J22,AF22,BB22) -> 40 | CA22: =CHOOSE($D$4,L22,AH22,BD22) -> 40 | CC22: =CHOOSE($D$4,N22,AJ22,BF22) -> 40 | CE22: =CHOOSE($D$4,P22,AL22,BH22) -> 40 | CG22: =CHOOSE($D$4,R22,AN22,BJ22) -> 40 | CI22: =CHOOSE($D$4,T22,AP22,BL22) -> 40 | CK22: =CHOOSE($D$4,V22,AR22,BN22) -> 40 | CM22: =CHOOSE($D$4,X22,AT22,BP22) -> 40 | CO22: =CHOOSE($D$4,Z22,AV22,BR22) -> 40
B23: Capital Expenditure 2 | D23: in $'mm | F23: 25.02 | H23: =+F23 -> 25.02 | J23: =+H23 -> 25.02 | L23: =+J23 -> 25.02 | N23: =+L23 -> 25.02 | P23: =+N23 -> 25.02 | R23: =+P23 -> 25.02 | T23: =+R23 -> 25.02 | V23: =+T23 -> 25.02 | X23: =+V23 -> 25.02 | Z23: =+X23 -> 25.02 | AB23: 30 | AD23: =+AB23 -> 30 | AF23: =+AD23 -> 30 | AH23: =+AF23 -> 30 | AJ23: =+AH23 -> 30 | AL23: =+AJ23 -> 30 | AN23: =+AL23 -> 30 | AP23: =+AN23 -> 30 | AR23: =+AP23 -> 30 | AT23: =+AR23 -> 30 | AV23: =+AT23 -> 30 | AX23: 45 | AZ23: =+AX23 -> 45 | BB23: =+AZ23 -> 45 | BD23: =+BB23 -> 45 | BF23: =+BD23 -> 45 | BH23: =+BF23 -> 45 | BJ23: =+BH23 -> 45 | BL23: =+BJ23 -> 45 | BN23: =+BL23 -> 45 | BP23: =+BN23 -> 45 | BR23: =+BP23 -> 45 | BU23: =CHOOSE($D$4,F23,AB23,AX23) -> 45 | BW23: =CHOOSE($D$4,H23,AD23,AZ23) -> 45 | BY23: =CHOOSE($D$4,J23,AF23,BB23) -> 45 | CA23: =CHOOSE($D$4,L23,AH23,BD23) -> 45 | CC23: =CHOOSE($D$4,N23,AJ23,BF23) -> 45 | CE23: =CHOOSE($D$4,P23,AL23,BH23) -> 45 | CG23: =CHOOSE($D$4,R23,AN23,BJ23) -> 45 | CI23: =CHOOSE($D$4,T23,AP23,BL23) -> 45 | CK23: =CHOOSE($D$4,V23,AR23,BN23) -> 45 | CM23: =CHOOSE($D$4,X23,AT23,BP23) -> 45 | CO23: =CHOOSE($D$4,Z23,AV23,BR23) -> 45
B25: Cash Tax | D25: % of Profit Before Tax | F25: 0.23 | H25: =F25 -> 0.23 | J25: =+H25 -> 0.23 | L25: =+J25 -> 0.23 | N25: =+L25 -> 0.23 | P25: =+N25 -> 0.23 | R25: =+P25 -> 0.23 | T25: =+R25 -> 0.23 | V25: =+T25 -> 0.23 | X25: =+V25 -> 0.23 | Z25: =+X25 -> 0.23 | AB25: 0.21 | AD25: =AB25 -> 0.21 | AF25: =+AD25 -> 0.21 | AH25: =+AF25 -> 0.21 | AJ25: =+AH25 -> 0.21 | AL25: =+AJ25 -> 0.21 | AN25: =+AL25 -> 0.21 | AP25: =+AN25 -> 0.21 | AR25: =+AP25 -> 0.21 | AT25: =+AR25 -> 0.21 | AV25: =+AT25 -> 0.21 | AX25: 0.21 | AZ25: =AX25 -> 0.21 | BB25: =+AZ25 -> 0.21 | BD25: =+BB25 -> 0.21 | BF25: =+BD25 -> 0.21 | BH25: =+BF25 -> 0.21 | BJ25: =+BH25 -> 0.21 | BL25: =+BJ25 -> 0.21 | BN25: =+BL25 -> 0.21 | BP25: =+BN25 -> 0.21 | BR25: =+BP25 -> 0.21 | BU25: =CHOOSE($D$4,F25,AB25,AX25) -> 0.21 | BW25: =CHOOSE($D$4,H25,AD25,AZ25) -> 0.21 | BY25: =CHOOSE($D$4,J25,AF25,BB25) -> 0.21 | CA25: =CHOOSE($D$4,L25,AH25,BD25) -> 0.21 | CC25: =CHOOSE($D$4,N25,AJ25,BF25) -> 0.21 | CE25: =CHOOSE($D$4,P25,AL25,BH25) -> 0.21 | CG25: =CHOOSE($D$4,R25,AN25,BJ25) -> 0.21 | CI25: =CHOOSE($D$4,T25,AP25,BL25) -> 0.21 | CK25: =CHOOSE($D$4,V25,AR25,BN25) -> 0.21 | CM25: =CHOOSE($D$4,X25,AT25,BP25) -> 0.21 | CO25: =CHOOSE($D$4,Z25,AV25,BR25) -> 0.21
B27: Working Capital Sources / (Uses) | D27: in $'mm | F27: 0.02 | H27: =+F27 -> 0.02 | J27: =+H27 -> 0.02 | L27: =+J27 -> 0.02 | N27: =+L27 -> 0.02 | P27: =+N27 -> 0.02 | R27: =+P27 -> 0.02 | T27: =+R27 -> 0.02 | V27: =+T27 -> 0.02 | X27: =+V27 -> 0.02 | Z27: =+X27 -> 0.02 | AB27: 10 | AD27: =+AB27 -> 10 | AF27: =+AD27 -> 10 | AH27: =+AF27 -> 10 | AJ27: =+AH27 -> 10 | AL27: =+AJ27 -> 10 | AN27: =+AL27 -> 10 | AP27: =+AN27 -> 10 | AR27: =+AP27 -> 10 | AT27: =+AR27 -> 10 | AV27: =+AT27 -> 10 | AX27: 20 | AZ27: =+AX27 -> 20 | BB27: =+AZ27 -> 20 | BD27: =+BB27 -> 20 | BF27: =+BD27 -> 20 | BH27: =+BF27 -> 20 | BJ27: =+BH27 -> 20 | BL27: =+BJ27 -> 20 | BN27: =+BL27 -> 20 | BP27: =+BN27 -> 20 | BR27: =+BP27 -> 20 | BU27: =CHOOSE($D$4,F27,AB27,AX27) -> 20 | BW27: =CHOOSE($D$4,H27,AD27,AZ27) -> 20 | BY27: =CHOOSE($D$4,J27,AF27,BB27) -> 20 | CA27: =CHOOSE($D$4,L27,AH27,BD27) -> 20 | CC27: =CHOOSE($D$4,N27,AJ27,BF27) -> 20 | CE27: =CHOOSE($D$4,P27,AL27,BH27) -> 20 | CG27: =CHOOSE($D$4,R27,AN27,BJ27) -> 20 | CI27: =CHOOSE($D$4,T27,AP27,BL27) -> 20 | CK27: =CHOOSE($D$4,V27,AR27,BN27) -> 20 | CM27: =CHOOSE($D$4,X27,AT27,BP27) -> 20 | CO27: =CHOOSE($D$4,Z27,AV27,BR27) -> 20

Sheet Financials
B2: ABC ltd
H4: Historical Financials | T4: Projected Financials
H6: 43465 | J6: =EOMONTH(H6,12) -> 43830 | L6: =EOMONTH(J6,12) -> 44196 | N6: =EOMONTH(L6,12) -> 44561 | P6: =EOMONTH(N6,12) -> 44926 | R6: =EOMONTH(P6,12) -> 45291 | T6: ='Financing Inputs'!T5 -> 45657 | V6: =EOMONTH(T6,12) -> 46022 | X6: =EOMONTH(V6,12) -> 46387 | Z6: =EOMONTH(X6,12) -> 46752 | AB6: =EOMONTH(Z6,12) -> 47118 | AD6: =EOMONTH(AB6,12) -> 47483 | AF6: =EOMONTH(AD6,12) -> 47848 | AH6: =EOMONTH(AF6,12) -> 48213 | AJ6: =EOMONTH(AH6,12) -> 48579 | AL6: =EOMONTH(AJ6,12) -> 48944 | AN6: =EOMONTH(AL6,12) -> 49309
B8: Financial Overview
B9: Total Revenue | H9: =H197 -> 552.31385 | J9: =J197 -> 702.8271 | L9: =L197 -> 714.31355 | N9: =N197 -> 696.87725 | P9: =P197 -> 640.9916 | R9: =R197 -> 1225.2416 | T9: =T123 -> 1241.9811 | V9: =V123 -> 1284.1343 | X9: =X123 -> 1371.6797 | Z9: =Z123 -> 1457.3677 | AB9: =AB123 -> 1532.927 | AD9: =AD123 -> 1603.2589 | AF9: =AF123 -> 1568.5568 | AH9: =AH123 -> 1534.7542 | AJ9: =AJ123 -> 1501.8197 | AL9: =AL123 -> 1469.7222 | AN9: =AN123 -> 1438.4314
B10: % Yr/Yr Growth | H10: na | J10: =IFERROR((J9/H9-1),"na") -> 0.27251399 | L10: =IFERROR((L9/J9-1),"na") -> 0.016343209 | N10: =IFERROR((N9/L9-1),"na") -> -0.024409869 | P10: =IFERROR((P9/N9-1),"na") -> -0.080194396 | R10: =IFERROR((R9/P9-1),"na") -> 0.9114784 | T10: =IFERROR((T9/R9-1),"na") -> 0.013662179 | V10: =IFERROR((V9/T9-1),"na") -> 0.033940343 | X10: =IFERROR((X9/V9-1),"na") -> 0.068174631 | Z10: =IFERROR((Z9/X9-1),"na") -> 0.062469406 | AB10: =IFERROR((AB9/Z9-1),"na") -> 0.051846376 | AD10: =IFERROR((AD9/AB9-1),"na") -> 0.045880839 | AF10: =IFERROR((AF9/AD9-1),"na") -> -0.021644752 | AH10: =IFERROR((AH9/AF9-1),"na") -> -0.021550101 | AJ10: =IFERROR((AJ9/AH9-1),"na") -> -0.021459181 | AL10: =IFERROR((AL9/AJ9-1),"na") -> -0.02137242 | AN10: =IFERROR((AN9/AL9-1),"na") -> -0.021290272
B12: Cost of Goods Sold | H12: =H198-H22 -> 389.9484 | J12: =J198-J22 -> 482.2314 | L12: =L198-L22 -> 476.28345 | N12: =N198-N22 -> 493.94015 | P12: =P198-P22 -> 491.92995 | R12: =R198-R22 -> 878.9932 | T12: =IF(AND(T$6>='Financing Inputs'!$T$5,T$6<='Financing Inputs'!$T$19),T9*(1-'Operating Inputs'!BU$17),0) -> 869.38675 | V12: =IF(AND(V$6>='Financing Inputs'!$T$5,V$6<='Financing Inputs'!$T$19),V9*(1-'Operating Inputs'!BW$17),0) -> 898.89403 | X12: =IF(AND(X$6>='Financing Inputs'!$T$5,X$6<='Financing Inputs'!$T$19),X9*(1-'Operating Inputs'!BY$17),0) -> 960.1758 | Z12: =IF(AND(Z$6>='Financing Inputs'!$T$5,Z$6<='Financing Inputs'!$T$19),Z9*(1-'Operating Inputs'!CA$17),0) -> 1020.1574 | AB12: =IF(AND(AB$6>='Financing Inputs'!$T$5,AB$6<='Financing Inputs'!$T$19),AB9*(1-'Operating Inputs'!CC$17),0) -> 1073.0489 | AD12: =IF(AND(AD$6>='Financing Inputs'!$T$5,AD$6<='Financing Inputs'!$T$19),AD9*(1-'Operating Inputs'!CE$17),0) -> 1122.2813 | AF12: =IF(AND(AF$6>='Financing Inputs'!$T$5,AF$6<='Financing Inputs'!$T$19),AF9*(1-'Operating Inputs'!CG$17),0) -> 1097.9898 | AH12: =IF(AND(AH$6>='Financing Inputs'!$T$5,AH$6<='Financing Inputs'!$T$19),AH9*(1-'Operating Inputs'!CI$17),0) -> 1074.328 | AJ12: =IF(AND(AJ$6>='Financing Inputs'!$T$5,AJ$6<='Financing Inputs'!$T$19),AJ9*(1-'Operating Inputs'!CK$17),0) -> 1051.2738 | AL12: =IF(AND(AL$6>='Financing Inputs'!$T$5,AL$6<='Financing Inputs'!$T$19),AL9*(1-'Operating Inputs'!CM$17),0) -> 1028.8055 | AN12: =IF(AND(AN$6>='Financing Inputs'!$T$5,AN$6<='Financing Inputs'!$T$19),AN9*(1-'Operating Inputs'!CO$17),0) -> 1006.902
B13: Gross Profit | H13: =+H9-H12 -> 162.36545 | J13: =+J9-J12 -> 220.5957 | L13: =+L9-L12 -> 238.0301 | N13: =+N9-N12 -> 202.9371 | P13: =+P9-P12 -> 149.06165 | R13: =+R9-R12 -> 346.2484 | T13: =+T9-T12 -> 372.59432 | V13: =+V9-V12 -> 385.2403 | X13: =+X9-X12 -> 411.50392 | Z13: =+Z9-Z12 -> 437.21032 | AB13: =+AB9-AB12 -> 459.87809 | AD13: =+AD9-AD12 -> 480.97768 | AF13: =+AF9-AF12 -> 470.56704 | AH13: =+AH9-AH12 -> 460.42627 | AJ13: =+AJ9-AJ12 -> 450.5459 | AL13: =+AL9-AL12 -> 440.91665 | AN13: =+AN9-AN12 -> 431.52941
B14: % Margin | H14: =IFERROR(H13/H$9,"na") -> 0.29397316 | J14: =IFERROR(J13/J$9,"na") -> 0.31386909 | L14: =IFERROR(L13/L$9,"na") -> 0.33322915 | N14: =IFERROR(N13/N$9,"na") -> 0.29120925 | P14: =IFERROR(P13/P$9,"na") -> 0.23254852 | R14: =IFERROR(R13/R$9,"na") -> 0.28259602 | T14: =IFERROR(T13/T$9,"na") -> 0.3 | V14: =IFERROR(V13/V$9,"na") -> 0.3 | X14: =IFERROR(X13/X$9,"na") -> 0.3 | Z14: =IFERROR(Z13/Z$9,"na") -> 0.3 | AB14: =IFERROR(AB13/AB$9,"na") -> 0.3 | AD14: =IFERROR(AD13/AD$9,"na") -> 0.3 | AF14: =IFERROR(AF13/AF$9,"na") -> 0.3 | AH14: =IFERROR(AH13/AH$9,"na") -> 0.3 | AJ14: =IFERROR(AJ13/AJ$9,"na") -> 0.3 | AL14: =IFERROR(AL13/AL$9,"na") -> 0.3 | AN14: =IFERROR(AN13/AN$9,"na") -> 0.3
B16: SG&A | H16: =-H203-H20 -> 49.761 | J16: =-J203-J20 -> 57.3439 | L16: =-L203-L20 -> 55.4534 | N16: =-N203-N20 -> 49.8902 | P16: =-P203-P20 -> 52.972 | R16: =-R203-R20 -> 83.52115 | T16: =T9*T17 -> 59.615091 | V16: =V9*V17 -> 61.638448 | X16: =X9*X17 -> 65.840626 | Z16: =Z9*Z17 -> 69.953651 | AB16: =AB9*AB17 -> 73.580495 | AD16: =AD9*AD17 -> 76.956429 | AF16: =AF9*AF17 -> 75.290727 | AH16: =AH9*AH17 -> 73.668204 | AJ16: =AJ9*AJ17 -> 72.087345 | AL16: =AL9*AL17 -> 70.546664 | AN16: =AN9*AN17 -> 69.044706
B17: % of Revenues | H17: =IFERROR(H16/H$9,"na") -> 0.090095514 | J17: =IFERROR(J16/J$9,"na") -> 0.081590337 | L17: =IFERROR(L16/L$9,"na") -> 0.077631735 | N17: =IFERROR(N16/N$9,"na") -> 0.071591087 | P17: =IFERROR(P16/P$9,"na") -> 0.082640709 | R17: =IFERROR(R16/R$9,"na") -> 0.068167086 | T17: =IF(AND(T$6>='Financing Inputs'!$T$5,T$6<='Financing Inputs'!$T$19),'Operating Inputs'!BU$20,0) -> 0.048 | V17: =IF(AND(V$6>='Financing Inputs'!$T$5,V$6<='Financing Inputs'!$T$19),'Operating Inputs'!BW$20,0) -> 0.048 | X17: =IF(AND(X$6>='Financing Inputs'!$T$5,X$6<='Financing Inputs'!$T$19),'Operating Inputs'!BY$20,0) -> 0.048 | Z17: =IF(AND(Z$6>='Financing Inputs'!$T$5,Z$6<='Financing Inputs'!$T$19),'Operating Inputs'!CA$20,0) -> 0.048 | AB17: =IF(AND(AB$6>='Financing Inputs'!$T$5,AB$6<='Financing Inputs'!$T$19),'Operating Inputs'!CC$20,0) -> 0.048 | AD17: =IF(AND(AD$6>='Financing Inputs'!$T$5,AD$6<='Financing Inputs'!$T$19),'Operating Inputs'!CE$20,0) -> 0.048 | AF17: =IF(AND(AF$6>='Financing Inputs'!$T$5,AF$6<='Financing Inputs'!$T$19),'Operating Inputs'!CG$20,0) -> 0.048 | AH17: =IF(AND(AH$6>='Financing Inputs'!$T$5,AH$6<='Financing Inputs'!$T$19),'Operating Inputs'!CI$20,0) -> 0.048 | AJ17: =IF(AND(AJ$6>='Financing Inputs'!$T$5,AJ$6<='Financing Inputs'!$T$19),'Operating Inputs'!CK$20,0) -> 0.048 | AL17: =IF(AND(AL$6>='Financing Inputs'!$T$5,AL$6<='Financing Inputs'!$T$19),'Operating Inputs'!CM$20,0) -> 0.048 | AN17: =IF(AND(AN$6>='Financing Inputs'!$T$5,AN$6<='Financing Inputs'!$T$19),'Operating Inputs'!CO$20,0) -> 0.048
B18: Goodwill impairment | H18: =-H204 -> 0 | J18: =-J204 -> 0 | L18: =-L204 -> 0 | N18: =-N204 -> 6.35455 | P18: =-P204 -> 0 | R18: =-R204 -> 0 | T18: 0 | V18: 0 | X18: 0 | Z18: 0 | AB18: 0 | AD18: 0 | AF18: 0 | AH18: 0 | AJ18: 0 | AL18: 0 | AN18: 0
B19: % of Revenues | H19: =IFERROR(H18/H$9,"na") -> 0 | J19: =IFERROR(J18/J$9,"na") -> 0 | L19: =IFERROR(L18/L$9,"na") -> 0 | N19: =IFERROR(N18/N$9,"na") -> 0.0091186073 | P19: =IFERROR(P18/P$9,"na") -> 0 | R19: =IFERROR(R18/R$9,"na") -> 0 | T19: =IFERROR(T18/T$9,"na") -> 0 | V19: =IFERROR(V18/V$9,"na") -> 0 | X19: =IFERROR(X18/X$9,"na") -> 0 | Z19: =IFERROR(Z18/Z$9,"na") -> 0 | AB19: =IFERROR(AB18/AB$9,"na") -> 0 | AD19: =IFERROR(AD18/AD$9,"na") -> 0 | AF19: =IFERROR(AF18/AF$9,"na") -> 0 | AH19: =IFERROR(AH18/AH$9,"na") -> 0 | AJ19: =IFERROR(AJ18/AJ$9,"na") -> 0 | AL19: =IFERROR(AL18/AL$9,"na") -> 0 | AN19: =IFERROR(AN18/AN$9,"na") -> 0
B20: Share Based Compensation | H20: =H225 -> 10.33315 | J20: =J225 -> 9.42875 | L20: =L225 -> 10.89555 | N20: =N225 -> 8.1396 | P20: =P225 -> 7.30455 | R20: =R225 -> 6.1845 | T20: =R20 -> 6.1845 | V20: 0 | X20: 0 | Z20: 0 | AB20: 0 | AD20: 0 | AF20: 0 | AH20: 0 | AJ20: 0 | AL20: 0 | AN20: 0
B21: % of Revenues | H21: =IFERROR(H20/H$9,"na") -> 0.018708837 | J21: =IFERROR(J20/J$9,"na") -> 0.013415462 | L21: =IFERROR(L20/L$9,"na") -> 0.015253176 | N21: =IFERROR(N20/N$9,"na") -> 0.011680106 | P21: =IFERROR(P20/P$9,"na") -> 0.011395703 | R21: =IFERROR(R20/R$9,"na") -> 0.0050475759 | T21: =IFERROR(T20/T$9,"na") -> 0.0049795445 | V21: =IFERROR(V20/V$9,"na") -> 0 | X21: =IFERROR(X20/X$9,"na") -> 0 | Z21: =IFERROR(Z20/Z$9,"na") -> 0 | AB21: =IFERROR(AB20/AB$9,"na") -> 0 | AD21: =IFERROR(AD20/AD$9,"na") -> 0 | AF21: =IFERROR(AF20/AF$9,"na") -> 0 | AH21: =IFERROR(AH20/AH$9,"na") -> 0 | AJ21: =IFERROR(AJ20/AJ$9,"na") -> 0 | AL21: =IFERROR(AL20/AL$9,"na") -> 0 | AN21: =IFERROR(AN20/AN$9,"na") -> 0
B22: Depreciation and amortization | H22: =H222 -> 103.30775 | J22: =J222 -> 104.9959 | L22: =L222 -> 107.084 | N22: =N222 -> 127.02355 | P22: =P222 -> 134.4383 | R22: =R222 -> 155.9102 | T22: =IF(AND(T$6>='Financing Inputs'!$T$5,T$6<='Financing Inputs'!$T$19),$R$22,0) -> 155.9102 | V22: =IF(AND(V$6>='Financing Inputs'!$T$5,V$6<='Financing Inputs'!$T$19),$R$22,0) -> 155.9102 | X22: =IF(AND(X$6>='Financing Inputs'!$T$5,X$6<='Financing Inputs'!$T$19),$R$22,0) -> 155.9102 | Z22: =IF(AND(Z$6>='Financing Inputs'!$T$5,Z$6<='Financing Inputs'!$T$19),$R$22,0) -> 155.9102 | AB22: =IF(AND(AB$6>='Financing Inputs'!$T$5,AB$6<='Financing Inputs'!$T$19),$R$22,0) -> 155.9102 | AD22: =IF(AND(AD$6>='Financing Inputs'!$T$5,AD$6<='Financing Inputs'!$T$19),$R$22,0) -> 155.9102 | AF22: =IF(AND(AF$6>='Financing Inputs'!$T$5,AF$6<='Financing Inputs'!$T$19),$R$22,0) -> 155.9102 | AH22: =IF(AND(AH$6>='Financing Inputs'!$T$5,AH$6<='Financing Inputs'!$T$19),$R$22,0) -> 155.9102 | AJ22: =IF(AND(AJ$6>='Financing Inputs'!$T$5,AJ$6<='Financing Inputs'!$T$19),$R$22,0) -> 155.9102 | AL22: =IF(AND(AL$6>='Financing Inputs'!$T$5,AL$6<='Financing Inputs'!$T$19),$R$22,0) -> 155.9102 | AN22: =IF(AND(AN$6>='Financing Inputs'!$T$5,AN$6<='Financing Inputs'!$T$19),$R$22,0) -> 155.9102
B23: Operating Income | H23: =+H13-H16-H20-H18-H22 -> -1.03645 | J23: =+J13-J16-J20-J18-J22 -> 48.82715 | L23: =+L13-L16-L20-L18-L22 -> 64.59715 | N23: =+N13-N16-N20-N18-N22 -> 11.5292 | P23: =+P13-P16-P20-P18-P22 -> -45.6532 | R23: =+R13-R16-R20-R18-R22 -> 100.63255 | T23: =+T13-T16-T20-T18-T22 -> 150.88453 | V23: =+V13-V16-V20-V18-V22 -> 167.69165 | X23: =+X13-X16-X20-X18-X22 -> 189.75309 | Z23: =+Z13-Z16-Z20-Z18-Z22 -> 211.34647 | AB23: =+AB13-AB16-AB20-AB18-AB22 -> 230.3874 | AD23: =+AD13-AD16-AD20-AD18-AD22 -> 248.11105 | AF23: =+AF13-AF16-AF20-AF18-AF22 -> 239.36611 | AH23: =+AH13-AH16-AH20-AH18-AH22 -> 230.84787 | AJ23: =+AJ13-AJ16-AJ20-AJ18-AJ22 -> 222.54836 | AL23: =+AL13-AL16-AL20-AL18-AL22 -> 214.45978 | AN23: =+AN13-AN16-AN20-AN18-AN22 -> 206.57451
B24: % Margin | H24: =IFERROR(H23/H$9,"na") -> -0.0018765599 | J24: =IFERROR(J23/J$9,"na") -> 0.069472492 | L24: =IFERROR(L23/L$9,"na") -> 0.090432486 | N24: =IFERROR(N23/N$9,"na") -> 0.01654409 | P24: =IFERROR(P23/P$9,"na") -> -0.071222774 | R24: =IFERROR(R23/R$9,"na") -> 0.082132822 | T24: =IFERROR(T23/T$9,"na") -> 0.12148698 | V24: =IFERROR(V23/V$9,"na") -> 0.13058731 | X24: =IFERROR(X23/X$9,"na") -> 0.13833629 | Z24: =IFERROR(Z23/Z$9,"na") -> 0.14501931 | AB24: =IFERROR(AB23/AB$9,"na") -> 0.15029248 | AD24: =IFERROR(AD23/AD$9,"na") -> 0.1547542 | AF24: =IFERROR(AF23/AF$9,"na") -> 0.15260277 | AH24: =IFERROR(AH23/AH$9,"na") -> 0.15041357 | AJ24: =IFERROR(AJ23/AJ$9,"na") -> 0.14818581 | AL24: =IFERROR(AL23/AL$9,"na") -> 0.14591859 | AN24: =IFERROR(AN23/AN$9,"na") -> 0.14361096
B26: +Depreciation and amortization | H26: =H22 -> 103.30775 | J26: =J22 -> 104.9959 | L26: =L22 -> 107.084 | N26: =N22 -> 127.02355 | P26: =P22 -> 134.4383 | R26: =R22 -> 155.9102 | T26: =T22 -> 155.9102 | V26: =V22 -> 155.9102 | X26: =X22 -> 155.9102 | Z26: =Z22 -> 155.9102 | AB26: =AB22 -> 155.9102 | AD26: =AD22 -> 155.9102 | AF26: =AF22 -> 155.9102 | AH26: =AH22 -> 155.9102 | AJ26: =AJ22 -> 155.9102 | AL26: =AL22 -> 155.9102 | AN26: =AN22 -> 155.9102
B27: +Goodwill Impairment / Write-off | H27: =H18 -> 0 | J27: =J18 -> 0 | L27: =L18 -> 0 | N27: =N18 -> 6.35455 | P27: =P18 -> 0 | R27: =R18 -> 0 | T27: =T18 -> 0 | V27: =V18 -> 0 | X27: =X18 -> 0 | Z27: =Z18 -> 0 | AB27: =AB18 -> 0 | AD27: =AD18 -> 0 | AF27: =AF18 -> 0 | AH27: =AH18 -> 0 | AJ27: =AJ18 -> 0 | AL27: =AL18 -> 0 | AN27: =AN18 -> 0
B28: +Share Based Compensation | H28: =H20 -> 10.33315 | J28: =J20 -> 9.42875 | L28: =L20 -> 10.89555 | N28: =N20 -> 8.1396 | P28: =P20 -> 7.30455 | R28: =R20 -> 6.1845 | T28: =T20 -> 6.1845 | V28: =V20 -> 0 | X28: =X20 -> 0 | Z28: =Z20 -> 0 | AB28: =AB20 -> 0 | AD28: =AD20 -> 0 | AF28: =AF20 -> 0 | AH28: =AH20 -> 0 | AJ28: =AJ20 -> 0 | AL28: =AL20 -> 0 | AN28: =AN20 -> 0
B29: EBITDA | H29: =+H23+H26+H27+H28 -> 112.60445 | J29: =+J23+J26+J27+J28 -> 163.2518 | L29: =+L23+L26+L27+L28 -> 182.5767 | N29: =+N23+N26+N27+N28 -> 153.0469 | P29: =+P23+P26+P27+P28 -> 96.08965 | R29: =+R23+R26+R27+R28 -> 262.72725 | T29: =+T23+T26+T27+T28 -> 312.97923 | V29: =+V23+V26+V27+V28 -> 323.60185 | X29: =+X23+X26+X27+X28 -> 345.66329 | Z29: =+Z23+Z26+Z27+Z28 -> 367.25667 | AB29: =+AB23+AB26+AB27+AB28 -> 386.2976 | AD29: =+AD23+AD26+AD27+AD28 -> 404.02125 | AF29: =+AF23+AF26+AF27+AF28 -> 395.27631 | AH29: =+AH23+AH26+AH27+AH28 -> 386.75807 | AJ29: =+AJ23+AJ26+AJ27+AJ28 -> 378.45856 | AL29: =+AL23+AL26+AL27+AL28 -> 370.36998 | AN29: =+AN23+AN26+AN27+AN28 -> 362.48471
B30: % Margin | H30: =IFERROR(H29/H$9,"na") -> 0.20387765 | J30: =IFERROR(J29/J$9,"na") -> 0.23227875 | L30: =IFERROR(L29/L$9,"na") -> 0.25559742 | N30: =IFERROR(N29/N$9,"na") -> 0.21961816 | P30: =IFERROR(P29/P$9,"na") -> 0.14990781 | R30: =IFERROR(R29/R$9,"na") -> 0.21442893 | T30: =IFERROR(T29/T$9,"na") -> 0.252 | V30: =IFERROR(V29/V$9,"na") -> 0.252 | X30: =IFERROR(X29/X$9,"na") -> 0.252 | Z30: =IFERROR(Z29/Z$9,"na") -> 0.252 | AB30: =IFERROR(AB29/AB$9,"na") -> 0.252 | AD30: =IFERROR(AD29/AD$9,"na") -> 0.252 | AF30: =IFERROR(AF29/AF$9,"na") -> 0.252 | AH30: =IFERROR(AH29/AH$9,"na") -> 0.252 | AJ30: =IFERROR(AJ29/AJ$9,"na") -> 0.252 | AL30: =IFERROR(AL29/AL$9,"na") -> 0.252 | AN30: =IFERROR(AN29/AN$9,"na") -> 0.252
B31: % Yr/Yr Growth | H31: na | J31: =IFERROR((J29/H29-1),"na") -> 0.44978107 | L31: =IFERROR((L29/J29-1),"na") -> 0.11837481 | N31: =IFERROR((N29/L29-1),"na") -> -0.16173915 | P31: =IFERROR((P29/N29-1),"na") -> -0.37215553 | R31: =IFERROR((R29/P29-1),"na") -> 1.7341889 | T31: =IFERROR((T29/R29-1),"na") -> 0.19127053 | V31: =IFERROR((V29/T29-1),"na") -> 0.033940343 | X31: =IFERROR((X29/V29-1),"na") -> 0.068174631 | Z31: =IFERROR((Z29/X29-1),"na") -> 0.062469406 | AB31: =IFERROR((AB29/Z29-1),"na") -> 0.051846376 | AD31: =IFERROR((AD29/AB29-1),"na") -> 0.045880839 | AF31: =IFERROR((AF29/AD29-1),"na") -> -0.021644752 | AH31: =IFERROR((AH29/AF29-1),"na") -> -0.021550101 | AJ31: =IFERROR((AJ29/AH29-1),"na") -> -0.021459181 | AL31: =IFERROR((AL29/AJ29-1),"na") -> -0.02137242 | AN31: =IFERROR((AN29/AL29-1),"na") -> -0.021290272
B33: Capital Expenditures | H33: =H247 -> -219.57065 | J33: =J247 -> -130.22885 | L33: =L247 -> -133.8113 | N33: =N247 -> -19.2318 | P33: =P247 -> -7.9059 | R33: =R247 -> -18.6086 | T33: =-IF(AND(T$6>='Financing Inputs'!$T$5,T$6<='Financing Inputs'!$T$19),'Operating Inputs'!BU$22,0) -> -40 | V33: =-IF(AND(V$6>='Financing Inputs'!$T$5,V$6<='Financing Inputs'!$T$19),'Operating Inputs'!BW$22,0) -> -40 | X33: =-IF(AND(X$6>='Financing Inputs'!$T$5,X$6<='Financing Inputs'!$T$19),'Operating Inputs'!BY$22,0) -> -40 | Z33: =-IF(AND(Z$6>='Financing Inputs'!$T$5,Z$6<='Financing Inputs'!$T$19),'Operating Inputs'!CA$22,0) -> -40 | AB33: =-IF(AND(AB$6>='Financing Inputs'!$T$5,AB$6<='Financing Inputs'!$T$19),'Operating Inputs'!CC$22,0) -> -40 | AD33: =-IF(AND(AD$6>='Financing Inputs'!$T$5,AD$6<='Financing Inputs'!$T$19),'Operating Inputs'!CE$22,0) -> -40 | AF33: =-IF(AND(AF$6>='Financing Inputs'!$T$5,AF$6<='Financing Inputs'!$T$19),'Operating Inputs'!CG$22,0) -> -40 | AH33: =-IF(AND(AH$6>='Financing Inputs'!$T$5,AH$6<='Financing Inputs'!$T$19),'Operating Inputs'!CI$22,0) -> -40 | AJ33: =-IF(AND(AJ$6>='Financing Inputs'!$T$5,AJ$6<='Financing Inputs'!$T$19),'Operating Inputs'!CK$22,0) -> -40 | AL33: =-IF(AND(AL$6>='Financing Inputs'!$T$5,AL$6<='Financing Inputs'!$T$19),'Operating Inputs'!CM$22,0) -> -40 | AN33: =-IF(AND(AN$6>='Financing Inputs'!$T$5,AN$6<='Financing Inputs'!$T$19),'Operating Inputs'!CO$22,0) -> -40
B34: Deferred Recertification and Dry Dock costs, net | H34: =+H240 -> 0 | J34: =+J240 -> 0 | L34: =+L240 -> 0 | N34: =+N240 -> 0 | P34: =+P240 -> -9.139 | R34: =+R240 -> -59.3959 | T34: =-IF(AND(T$6>='Financing Inputs'!$T$5,T$6<='Financing Inputs'!$T$19),'Operating Inputs'!BU$23,0) -> -45 | V34: =-IF(AND(V$6>='Financing Inputs'!$T$5,V$6<='Financing Inputs'!$T$19),'Operating Inputs'!BW$23,0) -> -45 | X34: =-IF(AND(X$6>='Financing Inputs'!$T$5,X$6<='Financing Inputs'!$T$19),'Operating Inputs'!BY$23,0) -> -45 | Z34: =-IF(AND(Z$6>='Financing Inputs'!$T$5,Z$6<='Financing Inputs'!$T$19),'Operating Inputs'!CA$23,0) -> -45 | AB34: =-IF(AND(AB$6>='Financing Inputs'!$T$5,AB$6<='Financing Inputs'!$T$19),'Operating Inputs'!CC$23,0) -> -45 | AD34: =-IF(AND(AD$6>='Financing Inputs'!$T$5,AD$6<='Financing Inputs'!$T$19),'Operating Inputs'!CE$23,0) -> -45 | AF34: =-IF(AND(AF$6>='Financing Inputs'!$T$5,AF$6<='Financing Inputs'!$T$19),'Operating Inputs'!CG$23,0) -> -45 | AH34: =-IF(AND(AH$6>='Financing Inputs'!$T$5,AH$6<='Financing Inputs'!$T$19),'Operating Inputs'!CI$23,0) -> -45 | AJ34: =-IF(AND(AJ$6>='Financing Inputs'!$T$5,AJ$6<='Financing Inputs'!$T$19),'Operating Inputs'!CK$23,0) -> -45 | AL34: =-IF(AND(AL$6>='Financing Inputs'!$T$5,AL$6<='Financing Inputs'!$T$19),'Operating Inputs'!CM$23,0) -> -45 | AN34: =-IF(AND(AN$6>='Financing Inputs'!$T$5,AN$6<='Financing Inputs'!$T$19),'Operating Inputs'!CO$23,0) -> -45
B35: Total Capital Expenditure | H35: =SUM(H33:H34) -> -219.57065 | J35: =SUM(J33:J34) -> -130.22885 | L35: =SUM(L33:L34) -> -133.8113 | N35: =SUM(N33:N34) -> -19.2318 | P35: =SUM(P33:P34) -> -17.0449 | R35: =SUM(R33:R34) -> -78.0045 | T35: =SUM(T33:T34) -> -85 | V35: =SUM(V33:V34) -> -85 | X35: =SUM(X33:X34) -> -85 | Z35: =SUM(Z33:Z34) -> -85 | AB35: =SUM(AB33:AB34) -> -85 | AD35: =SUM(AD33:AD34) -> -85 | AF35: =SUM(AF33:AF34) -> -85 | AH35: =SUM(AH33:AH34) -> -85 | AJ35: =SUM(AJ33:AJ34) -> -85 | AL35: =SUM(AL33:AL34) -> -85 | AN35: =SUM(AN33:AN34) -> -85
B36: Operating Cash Flow | H36: =+H29+H35 -> -106.9662 | J36: =+J29+J35 -> 33.02295 | L36: =+L29+L35 -> 48.7654 | N36: =+N29+N35 -> 133.8151 | P36: =+P29+P35 -> 79.04475 | R36: =+R29+R35 -> 184.72275 | T36: =+T29+T35 -> 227.97923 | V36: =+V29+V35 -> 238.60185 | X36: =+X29+X35 -> 260.66329 | Z36: =+Z29+Z35 -> 282.25667 | AB36: =+AB29+AB35 -> 301.2976 | AD36: =+AD29+AD35 -> 319.02125 | AF36: =+AF29+AF35 -> 310.27631 | AH36: =+AH29+AH35 -> 301.75807 | AJ36: =+AJ29+AJ35 -> 293.45856 | AL36: =+AL29+AL35 -> 285.36998 | AN36: =+AN29+AN35 -> 277.48471
B37: % Margin | H37: =IFERROR(H36/H$9,"na") -> -0.19366923 | J37: =IFERROR(J36/J$9,"na") -> 0.04698588 | L37: =IFERROR(L36/L$9,"na") -> 0.0682689 | N37: =IFERROR(N36/N$9,"na") -> 0.19202105 | P37: =IFERROR(P36/P$9,"na") -> 0.12331636 | R37: =IFERROR(R36/R$9,"na") -> 0.15076435 | T37: =IFERROR(T36/T$9,"na") -> 0.18356095 | V37: =IFERROR(V36/V$9,"na") -> 0.18580755 | X37: =IFERROR(X36/X$9,"na") -> 0.19003218 | Z37: =IFERROR(Z36/Z$9,"na") -> 0.19367567 | AB37: =IFERROR(AB36/AB$9,"na") -> 0.19655052 | AD37: =IFERROR(AD36/AD$9,"na") -> 0.19898299 | AF37: =IFERROR(AF36/AF$9,"na") -> 0.19781006 | AH37: =IFERROR(AH36/AH$9,"na") -> 0.19661654 | AJ37: =IFERROR(AJ36/AJ$9,"na") -> 0.19540199 | AL37: =IFERROR(AL36/AL$9,"na") -> 0.19416594 | AN37: =IFERROR(AN36/AN$9,"na") -> 0.19290785
B39: Cash Interest | H39: =H285 -> -7.5392 | J39: =J285 -> -4.2028 | L39: =L285 -> 1.4516 | N39: =N285 -> -17.4705 | P39: =P285 -> -19.0209 | R39: =R285 -> -14.0942 | T39: =Debt!H16+Debt!H23+Debt!H30+Debt!H37 -> 0 | V39: =Debt!J16+Debt!J23+Debt!J30+Debt!J37 -> -145.7325 | X39: =Debt!L16+Debt!L23+Debt!L30+Debt!L37 -> -142.20398 | Z39: =Debt!N16+Debt!N23+Debt!N30+Debt!N37 -> -138.3579 | AB39: =Debt!P16+Debt!P23+Debt!P30+Debt!P37 -> -134.16567 | AD39: =Debt!R16+Debt!R23+Debt!R30+Debt!R37 -> -129.59613 | AF39: =Debt!T16+Debt!T23+Debt!T30+Debt!T37 -> -124.61534 | AH39: =Debt!V16+Debt!V23+Debt!V30+Debt!V37 -> -119.18628 | AJ39: =Debt!X16+Debt!X23+Debt!X30+Debt!X37 -> -113.2686 | AL39: =Debt!Z16+Debt!Z23+Debt!Z30+Debt!Z37 -> -106.81834 | AN39: =Debt!AB16+Debt!AB23+Debt!AB30+Debt!AB37 -> -99.787543
B40: Refinance Interest Expense | T40: =Debt!H46+Debt!H54 -> 0 | V40: =Debt!J46+Debt!J54 -> 0 | X40: =Debt!L46+Debt!L54 -> 0 | Z40: =Debt!N46+Debt!N54 -> 0 | AB40: =Debt!P46+Debt!P54 -> 0 | AD40: =Debt!R46+Debt!R54 -> 0 | AF40: =Debt!T46+Debt!T54 -> 0 | AH40: =Debt!V46+Debt!V54 -> 0 | AJ40: =Debt!X46+Debt!X54 -> 0 | AL40: =Debt!Z46+Debt!Z54 -> 0 | AN40: =Debt!AB46+Debt!AB54 -> 0
B41: Cash Taxes (Paid) / Benefits | H41: =H291 -> -18.84895 | J41: =J291 -> -3.6727 | L41: =L291 -> -8.3885 | N41: =N291 -> -6.9407 | P41: =P291 -> 11.7477 | R41: =R291 -> -6.8761 | T41: =-IF(AND(T$6>='Financing Inputs'!$T$5,T$6<='Financing Inputs'!$T$19),'Operating Inputs'!BU$25,0)*(T23+T39+T40) -> -31.685751 | V41: =-IF(AND(V$6>='Financing Inputs'!$T$5,V$6<='Financing Inputs'!$T$19),'Operating Inputs'!BW$25,0)*(V23+V39+V40) -> -4.6114219 | X41: =-IF(AND(X$6>='Financing Inputs'!$T$5,X$6<='Financing Inputs'!$T$19),'Operating Inputs'!BY$25,0)*(X23+X39+X40) -> -9.9853124 | Z41: =-IF(AND(Z$6>='Financing Inputs'!$T$5,Z$6<='Financing Inputs'!$T$19),'Operating Inputs'!CA$25,0)*(Z23+Z39+Z40) -> -15.3276 | AB41: =-IF(AND(AB$6>='Financing Inputs'!$T$5,AB$6<='Financing Inputs'!$T$19),'Operating Inputs'!CC$25,0)*(AB23+AB39+AB40) -> -20.206563 | AD41: =-IF(AND(AD$6>='Financing Inputs'!$T$5,AD$6<='Financing Inputs'!$T$19),'Operating Inputs'!CE$25,0)*(AD23+AD39+AD40) -> -24.888133 | AF41: =-IF(AND(AF$6>='Financing Inputs'!$T$5,AF$6<='Financing Inputs'!$T$19),'Operating Inputs'!CG$25,0)*(AF23+AF39+AF40) -> -24.097662 | AH41: =-IF(AND(AH$6>='Financing Inputs'!$T$5,AH$6<='Financing Inputs'!$T$19),'Operating Inputs'!CI$25,0)*(AH23+AH39+AH40) -> -23.448934 | AJ41: =-IF(AND(AJ$6>='Financing Inputs'!$T$5,AJ$6<='Financing Inputs'!$T$19),'Operating Inputs'!CK$25,0)*(AJ23+AJ39+AJ40) -> -22.948749 | AL41: =-IF(AND(AL$6>='Financing Inputs'!$T$5,AL$6<='Financing Inputs'!$T$19),'Operating Inputs'!CM$25,0)*(AL23+AL39+AL40) -> -22.604704 | AN41: =-IF(AND(AN$6>='Financing Inputs'!$T$5,AN$6<='Financing Inputs'!$T$19),'Operating Inputs'!CO$25,0)*(AN23+AN39+AN40) -> -22.425262
B42: Working Capital Source / (Use) | H42: =+H236+H237+H239+H241 -> -35.1443 | J42: =+J236+J237+J239+J241 -> 33.95395 | L42: =+L236+L237+L239+L241 -> -14.89125 | N42: =+N236+N237+N239+N241 -> -38.7353 | P42: =+P236+P237+P239+P241 -> 49.98045 | R42: =+R236+R237+R239+R241 -> -43.59645 | T42: =IF(AND(T$6>='Financing Inputs'!$T$5,T$6<='Financing Inputs'!$T$19),'Operating Inputs'!BU$27,0) -> 20 | V42: =IF(AND(V$6>='Financing Inputs'!$T$5,V$6<='Financing Inputs'!$T$19),'Operating Inputs'!BW$27,0) -> 20 | X42: =IF(AND(X$6>='Financing Inputs'!$T$5,X$6<='Financing Inputs'!$T$19),'Operating Inputs'!BY$27,0) -> 20 | Z42: =IF(AND(Z$6>='Financing Inputs'!$T$5,Z$6<='Financing Inputs'!$T$19),'Operating Inputs'!CA$27,0) -> 20 | AB42: =IF(AND(AB$6>='Financing Inputs'!$T$5,AB$6<='Financing Inputs'!$T$19),'Operating Inputs'!CC$27,0) -> 20 | AD42: =IF(AND(AD$6>='Financing Inputs'!$T$5,AD$6<='Financing Inputs'!$T$19),'Operating Inputs'!CE$27,0) -> 20 | AF42: =IF(AND(AF$6>='Financing Inputs'!$T$5,AF$6<='Financing Inputs'!$T$19),'Operating Inputs'!CG$27,0) -> 20 | AH42: =IF(AND(AH$6>='Financing Inputs'!$T$5,AH$6<='Financing Inputs'!$T$19),'Operating Inputs'!CI$27,0) -> 20 | AJ42: =IF(AND(AJ$6>='Financing Inputs'!$T$5,AJ$6<='Financing Inputs'!$T$19),'Operating Inputs'!CK$27,0) -> 20 | AL42: =IF(AND(AL$6>='Financing Inputs'!$T$5,AL$6<='Financing Inputs'!$T$19),'Operating Inputs'!CM$27,0) -> 20 | AN42: =IF(AND(AN$6>='Financing Inputs'!$T$5,AN$6<='Financing Inputs'!$T$19),'Operating Inputs'!CO$27,0) -> 20
B43: Free Cash Flow | H43: =+H36+H39+H40+H41+H42 -> -168.49865 | J43: =+J36+J39+J40+J41+J42 -> 59.1014 | L43: =+L36+L39+L40+L41+L42 -> 26.93725 | N43: =+N36+N39+N40+N41+N42 -> 70.6686 | P43: =+P36+P39+P40+P41+P42 -> 121.752 | R43: =+R36+R39+R40+R41+R42 -> 120.156 | T43: =+T36+T39+T40+T41+T42 -> 216.29348 | V43: =+V36+V39+V40+V41+V42 -> 108.25793 | X43: =+X36+X39+X40+X41+X42 -> 128.47399 | Z43: =+Z36+Z39+Z40+Z41+Z42 -> 148.57117 | AB43: =+AB36+AB39+AB40+AB41+AB42 -> 166.92537 | AD43: =+AD36+AD39+AD40+AD41+AD42 -> 184.53699 | AF43: =+AF36+AF39+AF40+AF41+AF42 -> 181.56331 | AH43: =+AH36+AH39+AH40+AH41+AH42 -> 179.12286 | AJ43: =+AJ36+AJ39+AJ40+AJ41+AJ42 -> 177.24121 | AL43: =+AL36+AL39+AL40+AL41+AL42 -> 175.94694 | AN43: =+AN36+AN39+AN40+AN41+AN42 -> 175.2719
B45: Share Issued / (Repurchases) | H45: =H266 -> 208.5288 | J45: =J266 -> 0 | L45: =L266 -> 0 | N45: =N266 -> 0 | P45: =P266 -> 0 | R45: =R266 -> -11.3886 | T45: 0 | V45: 0 | X45: 0 | Z45: 0 | AB45: 0 | AD45: 0 | AF45: 0 | AH45: 0 | AJ45: 0 | AL45: 0 | AN45: 0
B46: Free Cash Flow Post-Equity Returns | H46: =+H43+H45 -> 40.03015 | J46: =+J43+J45 -> 59.1014 | L46: =+L43+L45 -> 26.93725 | N46: =+N43+N45 -> 70.6686 | P46: =+P43+P45 -> 121.752 | R46: =+R43+R45 -> 108.7674 | T46: =+T43+T45 -> 216.29348 | V46: =+V43+V45 -> 108.25793 | X46: =+X43+X45 -> 128.47399 | Z46: =+Z43+Z45 -> 148.57117 | AB46: =+AB43+AB45 -> 166.92537 | AD46: =+AD43+AD45 -> 184.53699 | AF46: =+AF43+AF45 -> 181.56331 | AH46: =+AH43+AH45 -> 179.12286 | AJ46: =+AJ43+AJ45 -> 177.24121 | AL46: =+AL43+AL45 -> 175.94694 | AN46: =+AN43+AN45 -> 175.2719
B48: Business Purchase | T48: =-IF(T$6='Financing Inputs'!$T$5,'Financing Inputs'!$L$7,0) -> -2159 | V48: =-IF(V$6='Financing Inputs'!$T$5,'Financing Inputs'!$L$7,0) -> 0 | X48: =-IF(X$6='Financing Inputs'!$T$5,'Financing Inputs'!$L$7,0) -> 0 | Z48: =-IF(Z$6='Financing Inputs'!$T$5,'Financing Inputs'!$L$7,0) -> 0 | AB48: =-IF(AB$6='Financing Inputs'!$T$5,'Financing Inputs'!$L$7,0) -> 0 | AD48: =-IF(AD$6='Financing Inputs'!$T$5,'Financing Inputs'!$L$7,0) -> 0 | AF48: =-IF(AF$6='Financing Inputs'!$T$5,'Financing Inputs'!$L$7,0) -> 0 | AH48: =-IF(AH$6='Financing Inputs'!$T$5,'Financing Inputs'!$L$7,0) -> 0 | AJ48: =-IF(AJ$6='Financing Inputs'!$T$5,'Financing Inputs'!$L$7,0) -> 0 | AL48: =-IF(AL$6='Financing Inputs'!$T$5,'Financing Inputs'!$L$7,0) -> 0 | AN48: =-IF(AN$6='Financing Inputs'!$T$5,'Financing Inputs'!$L$7,0) -> 0
B49: Business Sale | T49: =IF(T$6='Financing Inputs'!$T$19,'Financing Inputs'!$T$22,0) -> 0 | V49: =IF(V$6='Financing Inputs'!$T$19,'Financing Inputs'!$T$22,0) -> 0 | X49: =IF(X$6='Financing Inputs'!$T$19,'Financing Inputs'!$T$22,0) -> 0 | Z49: =IF(Z$6='Financing Inputs'!$T$19,'Financing Inputs'!$T$22,0) -> 0 | AB49: =IF(AB$6='Financing Inputs'!$T$19,'Financing Inputs'!$T$22,0) -> 0 | AD49: =IF(AD$6='Financing Inputs'!$T$19,'Financing Inputs'!$T$22,0) -> 0 | AF49: =IF(AF$6='Financing Inputs'!$T$19,'Financing Inputs'!$T$22,0) -> 0 | AH49: =IF(AH$6='Financing Inputs'!$T$19,'Financing Inputs'!$T$22,0) -> 0 | AJ49: =IF(AJ$6='Financing Inputs'!$T$19,'Financing Inputs'!$T$22,0) -> 0 | AL49: =IF(AL$6='Financing Inputs'!$T$19,'Financing Inputs'!$T$22,0) -> 0 | AN49: =IF(AN$6='Financing Inputs'!$T$19,'Financing Inputs'!$T$22,0) -> 1812.4235
B50: Equity 1 Issuance | T50: =IF(T$6='Financing Inputs'!$T$5,'Financing Inputs'!$F$7,0)-IF('Financing Inputs'!$T$31<>1,IF(T46+T53+T56<0,(T46+T53+T56)*'Financing Inputs'!$T$25,0),0)-IF('Financing Inputs'!$T$31=2,(Debt!H28+Debt!H35)*'Financing Inputs'!$T$25,0)-IF('Financing Inputs'!$T$31=1,IF(T46+T53+T54+T56<0,(T46+T53+T54+T56)*'Financing Inputs'!$T$25,0))-IF(T46+T53+IF('Financing Inputs'!$T$31=1,T54,0)+T56,0) -> 269.875 | V50: =IF(V$6='Financing Inputs'!$T$5,'Financing Inputs'!$F$7,0)-IF('Financing Inputs'!$T$31<>1,IF(V46+V53+V56<0,(V46+V53+V56)*'Financing Inputs'!$T$25,0),0)-IF('Financing Inputs'!$T$31=2,(Debt!J28+Debt!J35)*'Financing Inputs'!$T$25,0)-IF('Financing Inputs'!$T$31=1,IF(V46+V53+V54+V56<0,(V46+V53+V54+V56)*'Financing Inputs'!$T$25,0))-IF(V46+V53+IF('Financing Inputs'!$T$31=1,V54,0)+V56,0) -> 0 | X50: =IF(X$6='Financing Inputs'!$T$5,'Financing Inputs'!$F$7,0)-IF('Financing Inputs'!$T$31<>1,IF(X46+X53+X56<0,(X46+X53+X56)*'Financing Inputs'!$T$25,0),0)-IF('Financing Inputs'!$T$31=2,(Debt!L28+Debt!L35)*'Financing Inputs'!$T$25,0)-IF('Financing Inputs'!$T$31=1,IF(X46+X53+X54+X56<0,(X46+X53+X54+X56)*'Financing Inputs'!$T$25,0))-IF(X46+X53+IF('Financing Inputs'!$T$31=1,X54,0)+X56,0) -> 0 | Z50: =IF(Z$6='Financing Inputs'!$T$5,'Financing Inputs'!$F$7,0)-IF('Financing Inputs'!$T$31<>1,IF(Z46+Z53+Z56<0,(Z46+Z53+Z56)*'Financing Inputs'!$T$25,0),0)-IF('Financing Inputs'!$T$31=2,(Debt!N28+Debt!N35)*'Financing Inputs'!$T$25,0)-IF('Financing Inputs'!$T$31=1,IF(Z46+Z53+Z54+Z56<0,(Z46+Z53+Z54+Z56)*'Financing Inputs'!$T$25,0))-IF(Z46+Z53+IF('Financing Inputs'!$T$31=1,Z54,0)+Z56,0) -> 0 | AB50: =IF(AB$6='Financing Inputs'!$T$5,'Financing Inputs'!$F$7,0)-IF('Financing Inputs'!$T$31<>1,IF(AB46+AB53+AB56<0,(AB46+AB53+AB56)*'Financing Inputs'!$T$25,0),0)-IF('Financing Inputs'!$T$31=2,(Debt!P28+Debt!P35)*'Financing Inputs'!$T$25,0)-IF('Financing Inputs'!$T$31=1,IF(AB46+AB53+AB54+AB56<0,(AB46+AB53+AB54+AB56)*'Financing Inputs'!$T$25,0))-IF(AB46+AB53+IF('Financing Inputs'!$T$31=1,AB54,0)+AB56,0) -> 0 | AD50: =IF(AD$6='Financing Inputs'!$T$5,'Financing Inputs'!$F$7,0)-IF('Financing Inputs'!$T$31<>1,IF(AD46+AD53+AD56<0,(AD46+AD53+AD56)*'Financing Inputs'!$T$25,0),0)-IF('Financing Inputs'!$T$31=2,(Debt!R28+Debt!R35)*'Financing Inputs'!$T$25,0)-IF('Financing Inputs'!$T$31=1,IF(AD46+AD53+AD54+AD56<0,(AD46+AD53+AD54+AD56)*'Financing Inputs'!$T$25,0))-IF(AD46+AD53+IF('Financing Inputs'!$T$31=1,AD54,0)+AD56,0) -> 0 | AF50: =IF(AF$6='Financing Inputs'!$T$5,'Financing Inputs'!$F$7,0)-IF('Financing Inputs'!$T$31<>1,IF(AF46+AF53+AF56<0,(AF46+AF53+AF56)*'Financing Inputs'!$T$25,0),0)-IF('Financing Inputs'!$T$31=2,(Debt!T28+Debt!T35)*'Financing Inputs'!$T$25,0)-IF('Financing Inputs'!$T$31=1,IF(AF46+AF53+AF54+AF56<0,(AF46+AF53+AF54+AF56)*'Financing Inputs'!$T$25,0))-IF(AF46+AF53+IF('Financing Inputs'!$T$31=1,AF54,0)+AF56,0) -> 0 | AH50: =IF(AH$6='Financing Inputs'!$T$5,'Financing Inputs'!$F$7,0)-IF('Financing Inputs'!$T$31<>1,IF(AH46+AH53+AH56<0,(AH46+AH53+AH56)*'Financing Inputs'!$T$25,0),0)-IF('Financing Inputs'!$T$31=2,(Debt!V28+Debt!V35)*'Financing Inputs'!$T$25,0)-IF('Financing Inputs'!$T$31=1,IF(AH46+AH53+AH54+AH56<0,(AH46+AH53+AH54+AH56)*'Financing Inputs'!$T$25,0))-IF(AH46+AH53+IF('Financing Inputs'!$T$31=1,AH54,0)+AH56,0) -> 0 | AJ50: =IF(AJ$6='Financing Inputs'!$T$5,'Financing Inputs'!$F$7,0)-IF('Financing Inputs'!$T$31<>1,IF(AJ46+AJ53+AJ56<0,(AJ46+AJ53+AJ56)*'Financing Inputs'!$T$25,0),0)-IF('Financing Inputs'!$T$31=2,(Debt!X28+Debt!X35)*'Financing Inputs'!$T$25,0)-IF('Financing Inputs'!$T$31=1,IF(AJ46+AJ53+AJ54+AJ56<0,(AJ46+AJ53+AJ54+AJ56)*'Financing Inputs'!$T$25,0))-IF(AJ46+AJ53+IF('Financing Inputs'!$T$31=1,AJ54,0)+AJ56,0) -> 0 | AL50: =IF(AL$6='Financing Inputs'!$T$5,'Financing Inputs'!$F$7,0)-IF('Financing Inputs'!$T$31<>1,IF(AL46+AL53+AL56<0,(AL46+AL53+AL56)*'Financing Inputs'!$T$25,0),0)-IF('Financing Inputs'!$T$31=2,(Debt!Z28+Debt!Z35)*'Financing Inputs'!$T$25,0)-IF('Financing Inputs'!$T$31=1,IF(AL46+AL53+AL54+AL56<0,(AL46+AL53+AL54+AL56)*'Financing Inputs'!$T$25,0))-IF(AL46+AL53+IF('Financing Inputs'!$T$31=1,AL54,0)+AL56,0) -> 0 | AN50: =IF(AN$6='Financing Inputs'!$T$5,'Financing Inputs'!$F$7,0)-IF('Financing Inputs'!$T$31<>1,IF(AN46+AN53+AN56<0,(AN46+AN53+AN56)*'Financing Inputs'!$T$25,0),0)-IF('Financing Inputs'!$T$31=2,(Debt!AB28+Debt!AB35)*'Financing Inputs'!$T$25,0)-IF('Financing Inputs'!$T$31=1,IF(AN46+AN53+AN54+AN56<0,(AN46+AN53+AN54+AN56)*'Financing Inputs'!$T$25,0))-IF(AN46+AN53+IF('Financing Inputs'!$T$31=1,AN54,0)+AN56,0) -> 0
B51: Equity 2 Issuance | T51: =IF(T$6='Financing Inputs'!$T$5,'Financing Inputs'!$F$8,0) -> 269.875 | V51: =IF(V$6='Financing Inputs'!$T$5,'Financing Inputs'!$F$8,0) -> 0 | X51: =IF(X$6='Financing Inputs'!$T$5,'Financing Inputs'!$F$8,0) -> 0 | Z51: =IF(Z$6='Financing Inputs'!$T$5,'Financing Inputs'!$F$8,0) -> 0 | AB51: =IF(AB$6='Financing Inputs'!$T$5,'Financing Inputs'!$F$8,0) -> 0 | AD51: =IF(AD$6='Financing Inputs'!$T$5,'Financing Inputs'!$F$8,0) -> 0 | AF51: =IF(AF$6='Financing Inputs'!$T$5,'Financing Inputs'!$F$8,0) -> 0 | AH51: =IF(AH$6='Financing Inputs'!$T$5,'Financing Inputs'!$F$8,0) -> 0 | AJ51: =IF(AJ$6='Financing Inputs'!$T$5,'Financing Inputs'!$F$8,0) -> 0 | AL51: =IF(AL$6='Financing Inputs'!$T$5,'Financing Inputs'!$F$8,0) -> 0 | AN51: =IF(AN$6='Financing Inputs'!$T$5,'Financing Inputs'!$F$8,0) -> 0
...

Sheet Debt
B2: ABC ltd
H4: Projected Financials
B6: FYE - 12/31, in $mm | H6: ='Financing Inputs'!T5 -> 45657 | J6: =EOMONTH(H6,12) -> 46022 | L6: =EOMONTH(J6,12) -> 46387 | N6: =EOMONTH(L6,12) -> 46752 | P6: =EOMONTH(N6,12) -> 47118 | R6: =EOMONTH(P6,12) -> 47483 | T6: =EOMONTH(R6,12) -> 47848 | V6: =EOMONTH(T6,12) -> 48213 | X6: =EOMONTH(V6,12) -> 48579 | Z6: =EOMONTH(X6,12) -> 48944 | AB6: =EOMONTH(Z6,12) -> 49309
B8: Financial Overview
B10: Debt Calculation
B11: Debt Option - 1
B12: Opening Balance | J12: =H15 -> 1619.25 | L12: =J15 -> 1580.0442 | N12: =L15 -> 1537.31 | P12: =N15 -> 1490.7296 | R12: =P15 -> 1439.957 | T12: =R15 -> 1384.6149 | V12: =T15 -> 1324.292 | X12: =V15 -> 1258.54 | Z12: =X15 -> 1186.8704 | AB12: =Z15 -> 1108.7505
B13: Amortization | F13: =-IF('Financing Inputs'!$L$18=1,PMT('Financing Inputs'!$L$27,'Financing Inputs'!$L$28,'Financing Inputs'!$F$11),0) -> 184.93825 | J13: =-MIN(IF(Financials!BL$6>'Financing Inputs'!$T$19,0,Debt!$F$13+J16),J12) -> -39.205752 | L13: =-MIN(IF(Financials!BN$6>'Financing Inputs'!$T$19,0,Debt!$F$13+L16),L12) -> -42.734269 | N13: =-MIN(IF(Financials!BP$6>'Financing Inputs'!$T$19,0,Debt!$F$13+N16),N12) -> -46.580354 | P13: =-MIN(IF(Financials!BR$6>'Financing Inputs'!$T$19,0,Debt!$F$13+P16),P12) -> -50.772585 | R13: =-MIN(IF(Financials!BT$6>'Financing Inputs'!$T$19,0,Debt!$F$13+R16),R12) -> -55.342118 | T13: =-MIN(IF(Financials!BV$6>'Financing Inputs'!$T$19,0,Debt!$F$13+T16),T12) -> -60.322909 | V13: =-MIN(IF(Financials!BX$6>'Financing Inputs'!$T$19,0,Debt!$F$13+V16),V12) -> -65.75197 | X13: =-MIN(IF(Financials!BZ$6>'Financing Inputs'!$T$19,0,Debt!$F$13+X16),X12) -> -71.669648 | Z13: =-MIN(IF(Financials!CB$6>'Financing Inputs'!$T$19,0,Debt!$F$13+Z16),Z12) -> -78.119916 | AB13: =-MIN(IF(Financials!CD$6>'Financing Inputs'!$T$19,0,Debt!$F$13+AB16),AB12) -> -85.150709
B14: Balloon Payment | J14: =-IF(Financials!V$6='Financing Inputs'!$T$19,J12+J13,0) -> 0 | L14: =-IF(Financials!X$6='Financing Inputs'!$T$19,L12+L13,0) -> 0 | N14: =-IF(Financials!Z$6='Financing Inputs'!$T$19,N12+N13,0) -> 0 | P14: =-IF(Financials!AB$6='Financing Inputs'!$T$19,P12+P13,0) -> 0 | R14: =-IF(Financials!AD$6='Financing Inputs'!$T$19,R12+R13,0) -> 0 | T14: =-IF(Financials!AF$6='Financing Inputs'!$T$19,T12+T13,0) -> 0 | V14: =-IF(Financials!AH$6='Financing Inputs'!$T$19,V12+V13,0) -> 0 | X14: =-IF(Financials!AJ$6='Financing Inputs'!$T$19,X12+X13,0) -> 0 | Z14: =-IF(Financials!AL$6='Financing Inputs'!$T$19,Z12+Z13,0) -> 0 | AB14: =-IF(Financials!AN$6='Financing Inputs'!$T$19,AB12+AB13,0) -> -1023.5998
B15: Closing Balance | H15: =IF(AND('Financing Inputs'!$L$18=1,Financials!T$6='Financing Inputs'!$T$5),'Financing Inputs'!$F$11,SUM(H12:H14)) -> 1619.25 | J15: =IF(AND('Financing Inputs'!$L$18=1,Financials!V$6='Financing Inputs'!$T$5),'Financing Inputs'!$F$11,SUM(J12:J14)) -> 1580.0442 | L15: =IF(AND('Financing Inputs'!$L$18=1,Financials!X$6='Financing Inputs'!$T$5),'Financing Inputs'!$F$11,SUM(L12:L14)) -> 1537.31 | N15: =IF(AND('Financing Inputs'!$L$18=1,Financials!Z$6='Financing Inputs'!$T$5),'Financing Inputs'!$F$11,SUM(N12:N14)) -> 1490.7296 | P15: =IF(AND('Financing Inputs'!$L$18=1,Financials!AB$6='Financing Inputs'!$T$5),'Financing Inputs'!$F$11,SUM(P12:P14)) -> 1439.957 | R15: =IF(AND('Financing Inputs'!$L$18=1,Financials!AD$6='Financing Inputs'!$T$5),'Financing Inputs'!$F$11,SUM(R12:R14)) -> 1384.6149 | T15: =IF(AND('Financing Inputs'!$L$18=1,Financials!AF$6='Financing Inputs'!$T$5),'Financing Inputs'!$F$11,SUM(T12:T14)) -> 1324.292 | V15: =IF(AND('Financing Inputs'!$L$18=1,Financials!AH$6='Financing Inputs'!$T$5),'Financing Inputs'!$F$11,SUM(V12:V14)) -> 1258.54 | X15: =IF(AND('Financing Inputs'!$L$18=1,Financials!AJ$6='Financing Inputs'!$T$5),'Financing Inputs'!$F$11,SUM(X12:X14)) -> 1186.8704 | Z15: =IF(AND('Financing Inputs'!$L$18=1,Financials!AL$6='Financing Inputs'!$T$5),'Financing Inputs'!$F$11,SUM(Z12:Z14)) -> 1108.7505 | AB15: =IF(AND('Financing Inputs'!$L$18=1,Financials!AN$6='Financing Inputs'!$T$5),'Financing Inputs'!$F$11,SUM(AB12:AB14)) -> 0
B16: Interest Expense | F16: =IF('Financing Inputs'!$L$18=1,'Financing Inputs'!$L$27,0) -> 0.09 | J16: =-H15*Debt!$F$16 -> -145.7325 | L16: =-J15*Debt!$F$16 -> -142.20398 | N16: =-L15*Debt!$F$16 -> -138.3579 | P16: =-N15*Debt!$F$16 -> -134.16567 | R16: =-P15*Debt!$F$16 -> -129.59613 | T16: =-R15*Debt!$F$16 -> -124.61534 | V16: =-T15*Debt!$F$16 -> -119.18628 | X16: =-V15*Debt!$F$16 -> -113.2686 | Z16: =-X15*Debt!$F$16 -> -106.81834 | AB16: =-Z15*Debt!$F$16 -> -99.787543
B18: Debt Option - 2
B19: Opening Balance | J19: =H22 -> 0 | L19: =J22 -> 0 | N19: =L22 -> 0 | P19: =N22 -> 0 | R19: =P22 -> 0 | T19: =R22 -> 0 | V19: =T22 -> 0 | X19: =V22 -> 0 | Z19: =X22 -> 0 | AB19: =Z22 -> 0
B20: Amortization | F20: =IF('Financing Inputs'!$L$18=2,'Financing Inputs'!$F$11*'Financing Inputs'!$L$36,0) -> 0 | J20: =-MIN(IF(Financials!V$6>'Financing Inputs'!$J$36,IF(Financials!V$6>'Financing Inputs'!$T$19,0,Debt!$F$20),0)/IF(YEAR(Financials!V$6)=YEAR('Financing Inputs'!$J$36),IFERROR(12/(ROUND((YEARFRAC('Financing Inputs'!$J$36,Financials!V$6,1))*12,0)),1),1),J19) -> 0 | L20: =-MIN(IF(Financials!X$6>'Financing Inputs'!$J$36,IF(Financials!X$6>'Financing Inputs'!$T$19,0,Debt!$F$20),0)/IF(YEAR(Financials!X$6)=YEAR('Financing Inputs'!$J$36),IFERROR(12/(ROUND((YEARFRAC('Financing Inputs'!$J$36,Financials!X$6,1))*12,0)),1),1),L19) -> 0 | N20: =-MIN(IF(Financials!Z$6>'Financing Inputs'!$J$36,IF(Financials!Z$6>'Financing Inputs'!$T$19,0,Debt!$F$20),0)/IF(YEAR(Financials!Z$6)=YEAR('Financing Inputs'!$J$36),IFERROR(12/(ROUND((YEARFRAC('Financing Inputs'!$J$36,Financials!Z$6,1))*12,0)),1),1),N19) -> 0 | P20: =-MIN(IF(Financials!AB$6>'Financing Inputs'!$J$36,IF(Financials!AB$6>'Financing Inputs'!$T$19,0,Debt!$F$20),0)/IF(YEAR(Financials!AB$6)=YEAR('Financing Inputs'!$J$36),IFERROR(12/(ROUND((YEARFRAC('Financing Inputs'!$J$36,Financials!AB$6,1))*12,0)),1),1),P19) -> 0 | R20: =-MIN(IF(Financials!AD$6>'Financing Inputs'!$J$36,IF(Financials!AD$6>'Financing Inputs'!$T$19,0,Debt!$F$20),0)/IF(YEAR(Financials!AD$6)=YEAR('Financing Inputs'!$J$36),IFERROR(12/(ROUND((YEARFRAC('Financing Inputs'!$J$36,Financials!AD$6,1))*12,0)),1),1),R19) -> 0 | T20: =-MIN(IF(Financials!AF$6>'Financing Inputs'!$J$36,IF(Financials!AF$6>'Financing Inputs'!$T$19,0,Debt!$F$20),0)/IF(YEAR(Financials!AF$6)=YEAR('Financing Inputs'!$J$36),IFERROR(12/(ROUND((YEARFRAC('Financing Inputs'!$J$36,Financials!AF$6,1))*12,0)),1),1),T19) -> 0 | V20: =-MIN(IF(Financials!AH$6>'Financing Inputs'!$J$36,IF(Financials!AH$6>'Financing Inputs'!$T$19,0,Debt!$F$20),0)/IF(YEAR(Financials!AH$6)=YEAR('Financing Inputs'!$J$36),IFERROR(12/(ROUND((YEARFRAC('Financing Inputs'!$J$36,Financials!AH$6,1))*12,0)),1),1),V19) -> 0 | X20: =-MIN(IF(Financials!AJ$6>'Financing Inputs'!$J$36,IF(Financials!AJ$6>'Financing Inputs'!$T$19,0,Debt!$F$20),0)/IF(YEAR(Financials!AJ$6)=YEAR('Financing Inputs'!$J$36),IFERROR(12/(ROUND((YEARFRAC('Financing Inputs'!$J$36,Financials!AJ$6,1))*12,0)),1),1),X19) -> 0 | Z20: =-MIN(IF(Financials!AL$6>'Financing Inputs'!$J$36,IF(Financials!AL$6>'Financing Inputs'!$T$19,0,Debt!$F$20),0)/IF(YEAR(Financials!AL$6)=YEAR('Financing Inputs'!$J$36),IFERROR(12/(ROUND((YEARFRAC('Financing Inputs'!$J$36,Financials!AL$6,1))*12,0)),1),1),Z19) -> 0 | AB20: =-MIN(IF(Financials!AN$6>'Financing Inputs'!$J$36,IF(Financials!AN$6>'Financing Inputs'!$T$19,0,Debt!$F$20),0)/IF(YEAR(Financials!AN$6)=YEAR('Financing Inputs'!$J$36),IFERROR(12/(ROUND((YEARFRAC('Financing Inputs'!$J$36,Financials!AN$6,1))*12,0)),1),1),AB19) -> 0
B21: Balloon Payment | J21: =-IF(Financials!V$6='Financing Inputs'!$T$19,J19+J20,0) -> 0 | L21: =-IF(Financials!X$6='Financing Inputs'!$T$19,L19+L20,0) -> 0 | N21: =-IF(Financials!Z$6='Financing Inputs'!$T$19,N19+N20,0) -> 0 | P21: =-IF(Financials!AB$6='Financing Inputs'!$T$19,P19+P20,0) -> 0 | R21: =-IF(Financials!AD$6='Financing Inputs'!$T$19,R19+R20,0) -> 0 | T21: =-IF(Financials!AF$6='Financing Inputs'!$T$19,T19+T20,0) -> 0 | V21: =-IF(Financials!AH$6='Financing Inputs'!$T$19,V19+V20,0) -> 0 | X21: =-IF(Financials!AJ$6='Financing Inputs'!$T$19,X19+X20,0) -> 0 | Z21: =-IF(Financials!AL$6='Financing Inputs'!$T$19,Z19+Z20,0) -> 0 | AB21: =-IF(Financials!AN$6='Financing Inputs'!$T$19,AB19+AB20,0) -> 0
B22: Closing Balance | H22: =IF(AND('Financing Inputs'!$L$18=2,Financials!T$6='Financing Inputs'!$T$5),'Financing Inputs'!$F$11,SUM(H19:H21)) -> 0 | J22: =IF(AND('Financing Inputs'!$L$18=2,Financials!V$6='Financing Inputs'!$T$5),'Financing Inputs'!$F$11,SUM(J19:J21)) -> 0 | L22: =IF(AND('Financing Inputs'!$L$18=2,Financials!X$6='Financing Inputs'!$T$5),'Financing Inputs'!$F$11,SUM(L19:L21)) -> 0 | N22: =IF(AND('Financing Inputs'!$L$18=2,Financials!Z$6='Financing Inputs'!$T$5),'Financing Inputs'!$F$11,SUM(N19:N21)) -> 0 | P22: =IF(AND('Financing Inputs'!$L$18=2,Financials!AB$6='Financing Inputs'!$T$5),'Financing Inputs'!$F$11,SUM(P19:P21)) -> 0 | R22: =IF(AND('Financing Inputs'!$L$18=2,Financials!AD$6='Financing Inputs'!$T$5),'Financing Inputs'!$F$11,SUM(R19:R21)) -> 0 | T22: =IF(AND('Financing Inputs'!$L$18=2,Financials!AF$6='Financing Inputs'!$T$5),'Financing Inputs'!$F$11,SUM(T19:T21)) -> 0 | V22: =IF(AND('Financing Inputs'!$L$18=2,Financials!AH$6='Financing Inputs'!$T$5),'Financing Inputs'!$F$11,SUM(V19:V21)) -> 0 | X22: =IF(AND('Financing Inputs'!$L$18=2,Financials!AJ$6='Financing Inputs'!$T$5),'Financing Inputs'!$F$11,SUM(X19:X21)) -> 0 | Z22: =IF(AND('Financing Inputs'!$L$18=2,Financials!AL$6='Financing Inputs'!$T$5),'Financing Inputs'!$F$11,SUM(Z19:Z21)) -> 0 | AB22: =IF(AND('Financing Inputs'!$L$18=2,Financials!AN$6='Financing Inputs'!$T$5),'Financing Inputs'!$F$11,SUM(AB19:AB21)) -> 0
